11/13/2018 03:57:35 PM Data input is OK. 
11/13/2018 03:57:35 PM New Patient Added. 
11/13/2018 03:57:35 PM Exception on /api/new_patient [POST]
Traceback (most recent call last):
  File "/Users/kaseykwong/heart_rate_sentinel_server/.venv/lib/python3.6/site-packages/flask/app.py", line 2292, in wsgi_app
    response = self.full_dispatch_request()
  File "/Users/kaseykwong/heart_rate_sentinel_server/.venv/lib/python3.6/site-packages/flask/app.py", line 1815, in full_dispatch_request
    rv = self.handle_user_exception(e)
  File "/Users/kaseykwong/heart_rate_sentinel_server/.venv/lib/python3.6/site-packages/flask/app.py", line 1718, in handle_user_exception
    reraise(exc_type, exc_value, tb)
  File "/Users/kaseykwong/heart_rate_sentinel_server/.venv/lib/python3.6/site-packages/flask/_compat.py", line 35, in reraise
    raise value
  File "/Users/kaseykwong/heart_rate_sentinel_server/.venv/lib/python3.6/site-packages/flask/app.py", line 1813, in full_dispatch_request
    rv = self.dispatch_request()
  File "/Users/kaseykwong/heart_rate_sentinel_server/.venv/lib/python3.6/site-packages/flask/app.py", line 1799, in dispatch_request
    return self.view_functions[rule.endpoint](**req.view_args)
  File "server.py", line 37, in new_patient
    patient = create_user(info)
  File "server.py", line 55, in create_user
    p.save()
  File "/Users/kaseykwong/heart_rate_sentinel_server/.venv/lib/python3.6/site-packages/pymodm/base/models.py", line 464, in save
    self.full_clean()
  File "/Users/kaseykwong/heart_rate_sentinel_server/.venv/lib/python3.6/site-packages/pymodm/base/models.py", line 381, in full_clean
    self.clean_fields(exclude=exclude)
  File "/Users/kaseykwong/heart_rate_sentinel_server/.venv/lib/python3.6/site-packages/pymodm/base/models.py", line 367, in clean_fields
    raise ValidationError(error_dict)
pymodm.errors.ValidationError: {'heart_rate': ['must not be blank (was: [])'], 'heart_rate_time': ['must not be blank (was: [])']}
11/13/2018 03:57:35 PM 127.0.0.1 - - [13/Nov/2018 15:57:35] "POST /api/new_patient HTTP/1.1" 500 -
11/13/2018 04:02:48 PM Data input is OK. 
11/13/2018 04:02:48 PM New Patient Added. 
11/13/2018 04:02:48 PM Exception on /api/new_patient [POST]
Traceback (most recent call last):
  File "/Users/kaseykwong/heart_rate_sentinel_server/.venv/lib/python3.6/site-packages/flask/app.py", line 2292, in wsgi_app
    response = self.full_dispatch_request()
  File "/Users/kaseykwong/heart_rate_sentinel_server/.venv/lib/python3.6/site-packages/flask/app.py", line 1815, in full_dispatch_request
    rv = self.handle_user_exception(e)
  File "/Users/kaseykwong/heart_rate_sentinel_server/.venv/lib/python3.6/site-packages/flask/app.py", line 1718, in handle_user_exception
    reraise(exc_type, exc_value, tb)
  File "/Users/kaseykwong/heart_rate_sentinel_server/.venv/lib/python3.6/site-packages/flask/_compat.py", line 35, in reraise
    raise value
  File "/Users/kaseykwong/heart_rate_sentinel_server/.venv/lib/python3.6/site-packages/flask/app.py", line 1813, in full_dispatch_request
    rv = self.dispatch_request()
  File "/Users/kaseykwong/heart_rate_sentinel_server/.venv/lib/python3.6/site-packages/flask/app.py", line 1799, in dispatch_request
    return self.view_functions[rule.endpoint](**req.view_args)
  File "server.py", line 37, in new_patient
    patient = create_user(info)
  File "server.py", line 55, in create_user
    p.save()
  File "/Users/kaseykwong/heart_rate_sentinel_server/.venv/lib/python3.6/site-packages/pymodm/base/models.py", line 464, in save
    self.full_clean()
  File "/Users/kaseykwong/heart_rate_sentinel_server/.venv/lib/python3.6/site-packages/pymodm/base/models.py", line 381, in full_clean
    self.clean_fields(exclude=exclude)
  File "/Users/kaseykwong/heart_rate_sentinel_server/.venv/lib/python3.6/site-packages/pymodm/base/models.py", line 367, in clean_fields
    raise ValidationError(error_dict)
pymodm.errors.ValidationError: {'heart_rate': ['must not be blank (was: [])'], 'heart_rate_time': ['must not be blank (was: [])']}
11/13/2018 04:02:48 PM 127.0.0.1 - - [13/Nov/2018 16:02:48] "POST /api/new_patient HTTP/1.1" 500 -
11/13/2018 04:04:18 PM Data input is OK. 
11/13/2018 04:04:19 PM New Patient Added. 
11/13/2018 04:04:19 PM Exception on /api/new_patient [POST]
Traceback (most recent call last):
  File "/Users/kaseykwong/heart_rate_sentinel_server/.venv/lib/python3.6/site-packages/flask/app.py", line 2292, in wsgi_app
    response = self.full_dispatch_request()
  File "/Users/kaseykwong/heart_rate_sentinel_server/.venv/lib/python3.6/site-packages/flask/app.py", line 1815, in full_dispatch_request
    rv = self.handle_user_exception(e)
  File "/Users/kaseykwong/heart_rate_sentinel_server/.venv/lib/python3.6/site-packages/flask/app.py", line 1718, in handle_user_exception
    reraise(exc_type, exc_value, tb)
  File "/Users/kaseykwong/heart_rate_sentinel_server/.venv/lib/python3.6/site-packages/flask/_compat.py", line 35, in reraise
    raise value
  File "/Users/kaseykwong/heart_rate_sentinel_server/.venv/lib/python3.6/site-packages/flask/app.py", line 1813, in full_dispatch_request
    rv = self.dispatch_request()
  File "/Users/kaseykwong/heart_rate_sentinel_server/.venv/lib/python3.6/site-packages/flask/app.py", line 1799, in dispatch_request
    return self.view_functions[rule.endpoint](**req.view_args)
  File "server.py", line 37, in new_patient
    patient = create_user(info)
  File "server.py", line 55, in create_user
    logging.info("New Patient Added. ")
  File "/Users/kaseykwong/heart_rate_sentinel_server/.venv/lib/python3.6/site-packages/pymodm/base/models.py", line 464, in save
    self.full_clean()
  File "/Users/kaseykwong/heart_rate_sentinel_server/.venv/lib/python3.6/site-packages/pymodm/base/models.py", line 381, in full_clean
    self.clean_fields(exclude=exclude)
  File "/Users/kaseykwong/heart_rate_sentinel_server/.venv/lib/python3.6/site-packages/pymodm/base/models.py", line 367, in clean_fields
    raise ValidationError(error_dict)
pymodm.errors.ValidationError: {'heart_rate': ['must not be blank (was: [])'], 'heart_rate_time': ['must not be blank (was: [])']}
11/13/2018 04:04:19 PM 127.0.0.1 - - [13/Nov/2018 16:04:19] "POST /api/new_patient HTTP/1.1" 500 -
11/13/2018 04:05:28 PM Data input is OK. 
11/13/2018 04:05:28 PM New Patient Added. 
11/13/2018 04:05:28 PM Exception on /api/new_patient [POST]
Traceback (most recent call last):
  File "/Users/kaseykwong/heart_rate_sentinel_server/.venv/lib/python3.6/site-packages/flask/app.py", line 2292, in wsgi_app
    response = self.full_dispatch_request()
  File "/Users/kaseykwong/heart_rate_sentinel_server/.venv/lib/python3.6/site-packages/flask/app.py", line 1815, in full_dispatch_request
    rv = self.handle_user_exception(e)
  File "/Users/kaseykwong/heart_rate_sentinel_server/.venv/lib/python3.6/site-packages/flask/app.py", line 1718, in handle_user_exception
    reraise(exc_type, exc_value, tb)
  File "/Users/kaseykwong/heart_rate_sentinel_server/.venv/lib/python3.6/site-packages/flask/_compat.py", line 35, in reraise
    raise value
  File "/Users/kaseykwong/heart_rate_sentinel_server/.venv/lib/python3.6/site-packages/flask/app.py", line 1813, in full_dispatch_request
    rv = self.dispatch_request()
  File "/Users/kaseykwong/heart_rate_sentinel_server/.venv/lib/python3.6/site-packages/flask/app.py", line 1799, in dispatch_request
    return self.view_functions[rule.endpoint](**req.view_args)
  File "server.py", line 37, in new_patient
    patient = create_user(info)
  File "server.py", line 55, in create_user
    logging.info("New Patient Added. ")
  File "/Users/kaseykwong/heart_rate_sentinel_server/.venv/lib/python3.6/site-packages/pymodm/base/models.py", line 464, in save
    self.full_clean()
  File "/Users/kaseykwong/heart_rate_sentinel_server/.venv/lib/python3.6/site-packages/pymodm/base/models.py", line 381, in full_clean
    self.clean_fields(exclude=exclude)
  File "/Users/kaseykwong/heart_rate_sentinel_server/.venv/lib/python3.6/site-packages/pymodm/base/models.py", line 367, in clean_fields
    raise ValidationError(error_dict)
pymodm.errors.ValidationError: {'heart_rate': ['must not be blank (was: [])'], 'heart_rate_time': ['must not be blank (was: [])']}
11/13/2018 04:05:28 PM 127.0.0.1 - - [13/Nov/2018 16:05:28] "POST /api/new_patient HTTP/1.1" 500 -
11/13/2018 04:10:15 PM Data input is OK. 
11/13/2018 04:10:15 PM New Patient Added. 
11/13/2018 04:10:15 PM Exception on /api/new_patient [POST]
Traceback (most recent call last):
  File "/Users/kaseykwong/heart_rate_sentinel_server/.venv/lib/python3.6/site-packages/flask/app.py", line 2292, in wsgi_app
    response = self.full_dispatch_request()
  File "/Users/kaseykwong/heart_rate_sentinel_server/.venv/lib/python3.6/site-packages/flask/app.py", line 1815, in full_dispatch_request
    rv = self.handle_user_exception(e)
  File "/Users/kaseykwong/heart_rate_sentinel_server/.venv/lib/python3.6/site-packages/flask/app.py", line 1718, in handle_user_exception
    reraise(exc_type, exc_value, tb)
  File "/Users/kaseykwong/heart_rate_sentinel_server/.venv/lib/python3.6/site-packages/flask/_compat.py", line 35, in reraise
    raise value
  File "/Users/kaseykwong/heart_rate_sentinel_server/.venv/lib/python3.6/site-packages/flask/app.py", line 1813, in full_dispatch_request
    rv = self.dispatch_request()
  File "/Users/kaseykwong/heart_rate_sentinel_server/.venv/lib/python3.6/site-packages/flask/app.py", line 1799, in dispatch_request
    return self.view_functions[rule.endpoint](**req.view_args)
  File "server.py", line 37, in new_patient
    patient = create_user(info)
  File "server.py", line 55, in create_user
    logging.info("New Patient Added. ")
  File "/Users/kaseykwong/heart_rate_sentinel_server/.venv/lib/python3.6/site-packages/pymodm/base/models.py", line 464, in save
    self.full_clean()
  File "/Users/kaseykwong/heart_rate_sentinel_server/.venv/lib/python3.6/site-packages/pymodm/base/models.py", line 381, in full_clean
    self.clean_fields(exclude=exclude)
  File "/Users/kaseykwong/heart_rate_sentinel_server/.venv/lib/python3.6/site-packages/pymodm/base/models.py", line 367, in clean_fields
    raise ValidationError(error_dict)
pymodm.errors.ValidationError: {'heart_rate': ['must not be blank (was: [])'], 'heart_rate_time': ['must not be blank (was: [])']}
11/13/2018 04:10:15 PM 127.0.0.1 - - [13/Nov/2018 16:10:15] "POST /api/new_patient HTTP/1.1" 500 -
11/13/2018 04:12:42 PM Data input is OK. 
11/13/2018 04:12:42 PM New Patient Added. 
11/13/2018 04:12:42 PM Exception on /api/new_patient [POST]
Traceback (most recent call last):
  File "/Users/kaseykwong/heart_rate_sentinel_server/.venv/lib/python3.6/site-packages/flask/app.py", line 2292, in wsgi_app
    response = self.full_dispatch_request()
  File "/Users/kaseykwong/heart_rate_sentinel_server/.venv/lib/python3.6/site-packages/flask/app.py", line 1815, in full_dispatch_request
    rv = self.handle_user_exception(e)
  File "/Users/kaseykwong/heart_rate_sentinel_server/.venv/lib/python3.6/site-packages/flask/app.py", line 1718, in handle_user_exception
    reraise(exc_type, exc_value, tb)
  File "/Users/kaseykwong/heart_rate_sentinel_server/.venv/lib/python3.6/site-packages/flask/_compat.py", line 35, in reraise
    raise value
  File "/Users/kaseykwong/heart_rate_sentinel_server/.venv/lib/python3.6/site-packages/flask/app.py", line 1813, in full_dispatch_request
    rv = self.dispatch_request()
  File "/Users/kaseykwong/heart_rate_sentinel_server/.venv/lib/python3.6/site-packages/flask/app.py", line 1799, in dispatch_request
    return self.view_functions[rule.endpoint](**req.view_args)
  File "server.py", line 37, in new_patient
    patient = create_user(info)
  File "server.py", line 56, in create_user
    p.save()
  File "/Users/kaseykwong/heart_rate_sentinel_server/.venv/lib/python3.6/site-packages/pymodm/base/models.py", line 464, in save
    self.full_clean()
  File "/Users/kaseykwong/heart_rate_sentinel_server/.venv/lib/python3.6/site-packages/pymodm/base/models.py", line 381, in full_clean
    self.clean_fields(exclude=exclude)
  File "/Users/kaseykwong/heart_rate_sentinel_server/.venv/lib/python3.6/site-packages/pymodm/base/models.py", line 367, in clean_fields
    raise ValidationError(error_dict)
pymodm.errors.ValidationError: {'heart_rate': ['must not be blank (was: [])'], 'heart_rate_time': ['must not be blank (was: [])']}
11/13/2018 04:12:42 PM 127.0.0.1 - - [13/Nov/2018 16:12:42] "POST /api/new_patient HTTP/1.1" 500 -
11/13/2018 04:16:51 PM Data input is OK. 
11/13/2018 04:16:51 PM New Patient Added. 
11/13/2018 04:16:51 PM Exception on /api/new_patient [POST]
Traceback (most recent call last):
  File "/Users/kaseykwong/heart_rate_sentinel_server/.venv/lib/python3.6/site-packages/flask/app.py", line 2292, in wsgi_app
    response = self.full_dispatch_request()
  File "/Users/kaseykwong/heart_rate_sentinel_server/.venv/lib/python3.6/site-packages/flask/app.py", line 1815, in full_dispatch_request
    rv = self.handle_user_exception(e)
  File "/Users/kaseykwong/heart_rate_sentinel_server/.venv/lib/python3.6/site-packages/flask/app.py", line 1718, in handle_user_exception
    reraise(exc_type, exc_value, tb)
  File "/Users/kaseykwong/heart_rate_sentinel_server/.venv/lib/python3.6/site-packages/flask/_compat.py", line 35, in reraise
    raise value
  File "/Users/kaseykwong/heart_rate_sentinel_server/.venv/lib/python3.6/site-packages/flask/app.py", line 1813, in full_dispatch_request
    rv = self.dispatch_request()
  File "/Users/kaseykwong/heart_rate_sentinel_server/.venv/lib/python3.6/site-packages/flask/app.py", line 1799, in dispatch_request
    return self.view_functions[rule.endpoint](**req.view_args)
  File "server.py", line 37, in new_patient
    patient = create_user(info)
  File "server.py", line 56, in create_user
    p.save()
  File "/Users/kaseykwong/heart_rate_sentinel_server/.venv/lib/python3.6/site-packages/pymodm/base/models.py", line 464, in save
    self.full_clean()
  File "/Users/kaseykwong/heart_rate_sentinel_server/.venv/lib/python3.6/site-packages/pymodm/base/models.py", line 381, in full_clean
    self.clean_fields(exclude=exclude)
  File "/Users/kaseykwong/heart_rate_sentinel_server/.venv/lib/python3.6/site-packages/pymodm/base/models.py", line 367, in clean_fields
    raise ValidationError(error_dict)
pymodm.errors.ValidationError: {'heart_rate': ['must not be blank (was: [])'], 'heart_rate_time': ['must not be blank (was: [])']}
11/13/2018 04:16:51 PM 127.0.0.1 - - [13/Nov/2018 16:16:51] "POST /api/new_patient HTTP/1.1" 500 -
11/13/2018 04:25:12 PM Data input is OK. 
11/13/2018 04:25:13 PM New Patient Added. 
11/13/2018 04:25:13 PM Exception on /api/new_patient [POST]
Traceback (most recent call last):
  File "/Users/kaseykwong/heart_rate_sentinel_server/.venv/lib/python3.6/site-packages/flask/app.py", line 2292, in wsgi_app
    response = self.full_dispatch_request()
  File "/Users/kaseykwong/heart_rate_sentinel_server/.venv/lib/python3.6/site-packages/flask/app.py", line 1815, in full_dispatch_request
    rv = self.handle_user_exception(e)
  File "/Users/kaseykwong/heart_rate_sentinel_server/.venv/lib/python3.6/site-packages/flask/app.py", line 1718, in handle_user_exception
    reraise(exc_type, exc_value, tb)
  File "/Users/kaseykwong/heart_rate_sentinel_server/.venv/lib/python3.6/site-packages/flask/_compat.py", line 35, in reraise
    raise value
  File "/Users/kaseykwong/heart_rate_sentinel_server/.venv/lib/python3.6/site-packages/flask/app.py", line 1813, in full_dispatch_request
    rv = self.dispatch_request()
  File "/Users/kaseykwong/heart_rate_sentinel_server/.venv/lib/python3.6/site-packages/flask/app.py", line 1799, in dispatch_request
    return self.view_functions[rule.endpoint](**req.view_args)
  File "server.py", line 37, in new_patient
    patient = create_user(info)
  File "server.py", line 56, in create_user
    p.save()
  File "/Users/kaseykwong/heart_rate_sentinel_server/.venv/lib/python3.6/site-packages/pymodm/base/models.py", line 464, in save
    self.full_clean()
  File "/Users/kaseykwong/heart_rate_sentinel_server/.venv/lib/python3.6/site-packages/pymodm/base/models.py", line 381, in full_clean
    self.clean_fields(exclude=exclude)
  File "/Users/kaseykwong/heart_rate_sentinel_server/.venv/lib/python3.6/site-packages/pymodm/base/models.py", line 367, in clean_fields
    raise ValidationError(error_dict)
pymodm.errors.ValidationError: {'heart_rate': ['must not be blank (was: [])'], 'heart_rate_time': ['must not be blank (was: [])']}
11/13/2018 04:25:13 PM 127.0.0.1 - - [13/Nov/2018 16:25:13] "POST /api/new_patient HTTP/1.1" 500 -
11/13/2018 04:28:10 PM Data input is OK. 
11/13/2018 04:28:11 PM New Patient Added. 
11/13/2018 04:28:11 PM 127.0.0.1 - - [13/Nov/2018 16:28:11] "POST /api/new_patient HTTP/1.1" 200 -
11/13/2018 04:31:24 PM No data associated with patient id.
11/13/2018 04:31:24 PM 127.0.0.1 - - [13/Nov/2018 16:31:24] "GET /api/heart_rate/1 HTTP/1.1" 400 -
11/13/2018 04:31:26 PM 127.0.0.1 - - [13/Nov/2018 16:31:26] "GET /favicon.ico HTTP/1.1" 404 -
11/13/2018 04:31:52 PM No data associated with patient id.
11/13/2018 04:31:52 PM 127.0.0.1 - - [13/Nov/2018 16:31:52] "GET /api/heart_rate/1 HTTP/1.1" 400 -
11/13/2018 04:32:03 PM No data associated with patient id.
11/13/2018 04:32:03 PM 127.0.0.1 - - [13/Nov/2018 16:32:03] "GET /api/heart_rate/10 HTTP/1.1" 400 -
11/13/2018 08:41:27 PM Data input is OK. 
11/13/2018 08:41:27 PM Exception on /api/new_patient [POST]
Traceback (most recent call last):
  File "/Users/kaseykwong/heart_rate_sentinel_server/.venv/lib/python3.6/site-packages/flask/app.py", line 2292, in wsgi_app
    response = self.full_dispatch_request()
  File "/Users/kaseykwong/heart_rate_sentinel_server/.venv/lib/python3.6/site-packages/flask/app.py", line 1815, in full_dispatch_request
    rv = self.handle_user_exception(e)
  File "/Users/kaseykwong/heart_rate_sentinel_server/.venv/lib/python3.6/site-packages/flask/app.py", line 1718, in handle_user_exception
    reraise(exc_type, exc_value, tb)
  File "/Users/kaseykwong/heart_rate_sentinel_server/.venv/lib/python3.6/site-packages/flask/_compat.py", line 35, in reraise
    raise value
  File "/Users/kaseykwong/heart_rate_sentinel_server/.venv/lib/python3.6/site-packages/flask/app.py", line 1813, in full_dispatch_request
    rv = self.dispatch_request()
  File "/Users/kaseykwong/heart_rate_sentinel_server/.venv/lib/python3.6/site-packages/flask/app.py", line 1799, in dispatch_request
    return self.view_functions[rule.endpoint](**req.view_args)
  File "server.py", line 38, in new_patient
    patient = create_user(info)
  File "server.py", line 57, in create_user
    p.save()
  File "/Users/kaseykwong/heart_rate_sentinel_server/.venv/lib/python3.6/site-packages/pymodm/base/models.py", line 464, in save
    self.full_clean()
  File "/Users/kaseykwong/heart_rate_sentinel_server/.venv/lib/python3.6/site-packages/pymodm/base/models.py", line 381, in full_clean
    self.clean_fields(exclude=exclude)
  File "/Users/kaseykwong/heart_rate_sentinel_server/.venv/lib/python3.6/site-packages/pymodm/base/models.py", line 367, in clean_fields
    raise ValidationError(error_dict)
pymodm.errors.ValidationError: {'heart_rate': ["'int' object is not iterable"], 'heart_rate_time': ["'datetime.datetime' object is not iterable"]}
11/13/2018 08:41:27 PM 127.0.0.1 - - [13/Nov/2018 20:41:27] "POST /api/new_patient HTTP/1.1" 500 -
11/13/2018 08:42:41 PM Data input is OK. 
11/13/2018 08:42:41 PM New Patient Added. 
11/13/2018 08:42:41 PM 127.0.0.1 - - [13/Nov/2018 20:42:41] "POST /api/new_patient HTTP/1.1" 200 -
11/13/2018 08:43:37 PM No data associated with patient id.
11/13/2018 08:43:37 PM 127.0.0.1 - - [13/Nov/2018 20:43:37] "GET /api/heart_rate/2 HTTP/1.1" 400 -
11/13/2018 08:50:18 PM 127.0.0.1 - - [13/Nov/2018 20:50:18] "GET /api/heart_rate/2 HTTP/1.1" 200 -
11/13/2018 08:50:57 PM 127.0.0.1 - - [13/Nov/2018 20:50:57] "GET /api/heart_rate/10 HTTP/1.1" 200 -
11/13/2018 08:51:06 PM No data associated with patient id.
11/13/2018 08:51:06 PM 127.0.0.1 - - [13/Nov/2018 20:51:06] "GET /api/heart_rate/1 HTTP/1.1" 400 -
11/13/2018 08:52:10 PM 127.0.0.1 - - [13/Nov/2018 20:52:10] "GET /api/heart_rate/2 HTTP/1.1" 200 -
11/15/2018 02:45:33 PM 127.0.0.1 - - [15/Nov/2018 14:45:33] "GET /api/heart_rate/10 HTTP/1.1" 200 -
11/15/2018 03:45:07 PM Data input is OK. 
11/15/2018 03:45:07 PM New Patient Added. 
11/15/2018 03:45:07 PM 127.0.0.1 - - [15/Nov/2018 15:45:07] "POST /api/new_patient HTTP/1.1" 200 -
11/15/2018 03:45:42 PM 127.0.0.1 - - [15/Nov/2018 15:45:42] "GET /api/heart_rate/2 HTTP/1.1" 200 -
11/15/2018 03:46:39 PM Data input is OK. 
11/15/2018 03:46:40 PM New Patient Added. 
11/15/2018 03:46:40 PM 127.0.0.1 - - [15/Nov/2018 15:46:40] "POST /api/new_patient HTTP/1.1" 200 -
11/15/2018 03:46:49 PM 127.0.0.1 - - [15/Nov/2018 15:46:49] "GET /api/heart_rate/2 HTTP/1.1" 200 -
11/15/2018 03:47:52 PM Data input is OK. 
11/15/2018 03:47:52 PM New Patient Added. 
11/15/2018 03:47:52 PM 127.0.0.1 - - [15/Nov/2018 15:47:52] "POST /api/new_patient HTTP/1.1" 200 -
11/15/2018 03:47:52 PM Data input is OK. 
11/15/2018 03:47:52 PM Patient ID doesn't exist. Please create new patient first.
11/15/2018 03:47:52 PM 127.0.0.1 - - [15/Nov/2018 15:47:52] "POST /api/heart_rate HTTP/1.1" 400 -
11/15/2018 03:49:28 PM 127.0.0.1 - - [15/Nov/2018 15:49:28] "GET /api/heart_rate/2 HTTP/1.1" 200 -
11/15/2018 03:50:33 PM Data input is OK. 
11/15/2018 03:50:33 PM Exception on /api/heart_rate [POST]
Traceback (most recent call last):
  File "/Users/kaseykwong/heart_rate_sentinel_server/.venv/lib/python3.6/site-packages/flask/app.py", line 2292, in wsgi_app
    response = self.full_dispatch_request()
  File "/Users/kaseykwong/heart_rate_sentinel_server/.venv/lib/python3.6/site-packages/flask/app.py", line 1815, in full_dispatch_request
    rv = self.handle_user_exception(e)
  File "/Users/kaseykwong/heart_rate_sentinel_server/.venv/lib/python3.6/site-packages/flask/app.py", line 1718, in handle_user_exception
    reraise(exc_type, exc_value, tb)
  File "/Users/kaseykwong/heart_rate_sentinel_server/.venv/lib/python3.6/site-packages/flask/_compat.py", line 35, in reraise
    raise value
  File "/Users/kaseykwong/heart_rate_sentinel_server/.venv/lib/python3.6/site-packages/flask/app.py", line 1813, in full_dispatch_request
    rv = self.dispatch_request()
  File "/Users/kaseykwong/heart_rate_sentinel_server/.venv/lib/python3.6/site-packages/flask/app.py", line 1799, in dispatch_request
    return self.view_functions[rule.endpoint](**req.view_args)
  File "server.py", line 125, in heart_rate
    add_heart_rate(patient_number, hr, curr_time)
  File "server.py", line 143, in add_heart_rate
    if p.heart_rate_times[0] == p.created:
AttributeError: 'Patient' object has no attribute 'heart_rate_times'
11/15/2018 03:50:33 PM 127.0.0.1 - - [15/Nov/2018 15:50:33] "POST /api/heart_rate HTTP/1.1" 500 -
11/15/2018 03:51:35 PM 127.0.0.1 - - [15/Nov/2018 15:51:35] "GET /api/heart_rate/2 HTTP/1.1" 200 -
11/15/2018 03:53:38 PM Data input is OK. 
11/15/2018 03:53:38 PM Exception on /api/heart_rate [POST]
Traceback (most recent call last):
  File "/Users/kaseykwong/heart_rate_sentinel_server/.venv/lib/python3.6/site-packages/flask/app.py", line 2292, in wsgi_app
    response = self.full_dispatch_request()
  File "/Users/kaseykwong/heart_rate_sentinel_server/.venv/lib/python3.6/site-packages/flask/app.py", line 1815, in full_dispatch_request
    rv = self.handle_user_exception(e)
  File "/Users/kaseykwong/heart_rate_sentinel_server/.venv/lib/python3.6/site-packages/flask/app.py", line 1718, in handle_user_exception
    reraise(exc_type, exc_value, tb)
  File "/Users/kaseykwong/heart_rate_sentinel_server/.venv/lib/python3.6/site-packages/flask/_compat.py", line 35, in reraise
    raise value
  File "/Users/kaseykwong/heart_rate_sentinel_server/.venv/lib/python3.6/site-packages/flask/app.py", line 1813, in full_dispatch_request
    rv = self.dispatch_request()
  File "/Users/kaseykwong/heart_rate_sentinel_server/.venv/lib/python3.6/site-packages/flask/app.py", line 1799, in dispatch_request
    return self.view_functions[rule.endpoint](**req.view_args)
  File "server.py", line 125, in heart_rate
    add_heart_rate(patient_number, hr, curr_time)
  File "server.py", line 143, in add_heart_rate
    if p.heart_rate_times[0] == p.created:
AttributeError: 'Patient' object has no attribute 'heart_rate_times'
11/15/2018 03:53:38 PM 127.0.0.1 - - [15/Nov/2018 15:53:38] "POST /api/heart_rate HTTP/1.1" 500 -
11/15/2018 03:53:55 PM Data input is OK. 
11/15/2018 03:53:55 PM Exception on /api/heart_rate [POST]
Traceback (most recent call last):
  File "/Users/kaseykwong/heart_rate_sentinel_server/.venv/lib/python3.6/site-packages/flask/app.py", line 2292, in wsgi_app
    response = self.full_dispatch_request()
  File "/Users/kaseykwong/heart_rate_sentinel_server/.venv/lib/python3.6/site-packages/flask/app.py", line 1815, in full_dispatch_request
    rv = self.handle_user_exception(e)
  File "/Users/kaseykwong/heart_rate_sentinel_server/.venv/lib/python3.6/site-packages/flask/app.py", line 1718, in handle_user_exception
    reraise(exc_type, exc_value, tb)
  File "/Users/kaseykwong/heart_rate_sentinel_server/.venv/lib/python3.6/site-packages/flask/_compat.py", line 35, in reraise
    raise value
  File "/Users/kaseykwong/heart_rate_sentinel_server/.venv/lib/python3.6/site-packages/flask/app.py", line 1813, in full_dispatch_request
    rv = self.dispatch_request()
  File "/Users/kaseykwong/heart_rate_sentinel_server/.venv/lib/python3.6/site-packages/flask/app.py", line 1799, in dispatch_request
    return self.view_functions[rule.endpoint](**req.view_args)
  File "server.py", line 125, in heart_rate
    add_heart_rate(patient_number, hr, curr_time)
  File "server.py", line 143, in add_heart_rate
    if p.heart_rate_times[0] == p.created:
AttributeError: 'Patient' object has no attribute 'heart_rate_times'
11/15/2018 03:53:55 PM 127.0.0.1 - - [15/Nov/2018 15:53:55] "POST /api/heart_rate HTTP/1.1" 500 -
11/15/2018 03:54:55 PM Data input is OK. 
11/15/2018 03:54:55 PM Exception on /api/heart_rate [POST]
Traceback (most recent call last):
  File "/Users/kaseykwong/heart_rate_sentinel_server/.venv/lib/python3.6/site-packages/flask/app.py", line 2292, in wsgi_app
    response = self.full_dispatch_request()
  File "/Users/kaseykwong/heart_rate_sentinel_server/.venv/lib/python3.6/site-packages/flask/app.py", line 1815, in full_dispatch_request
    rv = self.handle_user_exception(e)
  File "/Users/kaseykwong/heart_rate_sentinel_server/.venv/lib/python3.6/site-packages/flask/app.py", line 1718, in handle_user_exception
    reraise(exc_type, exc_value, tb)
  File "/Users/kaseykwong/heart_rate_sentinel_server/.venv/lib/python3.6/site-packages/flask/_compat.py", line 35, in reraise
    raise value
  File "/Users/kaseykwong/heart_rate_sentinel_server/.venv/lib/python3.6/site-packages/flask/app.py", line 1813, in full_dispatch_request
    rv = self.dispatch_request()
  File "/Users/kaseykwong/heart_rate_sentinel_server/.venv/lib/python3.6/site-packages/flask/app.py", line 1799, in dispatch_request
    return self.view_functions[rule.endpoint](**req.view_args)
  File "server.py", line 125, in heart_rate
    add_heart_rate(patient_number, hr, curr_time)
  File "server.py", line 143, in add_heart_rate
    if p.heart_rate_time[0] == p.created:
AttributeError: 'Patient' object has no attribute 'heart_rate_times'
11/15/2018 03:54:55 PM 127.0.0.1 - - [15/Nov/2018 15:54:55] "POST /api/heart_rate HTTP/1.1" 500 -
11/15/2018 03:57:11 PM Data input is OK. 
11/15/2018 03:57:11 PM Exception on /api/heart_rate [POST]
Traceback (most recent call last):
  File "/Users/kaseykwong/heart_rate_sentinel_server/.venv/lib/python3.6/site-packages/flask/app.py", line 2292, in wsgi_app
    response = self.full_dispatch_request()
  File "/Users/kaseykwong/heart_rate_sentinel_server/.venv/lib/python3.6/site-packages/flask/app.py", line 1815, in full_dispatch_request
    rv = self.handle_user_exception(e)
  File "/Users/kaseykwong/heart_rate_sentinel_server/.venv/lib/python3.6/site-packages/flask/app.py", line 1718, in handle_user_exception
    reraise(exc_type, exc_value, tb)
  File "/Users/kaseykwong/heart_rate_sentinel_server/.venv/lib/python3.6/site-packages/flask/_compat.py", line 35, in reraise
    raise value
  File "/Users/kaseykwong/heart_rate_sentinel_server/.venv/lib/python3.6/site-packages/flask/app.py", line 1813, in full_dispatch_request
    rv = self.dispatch_request()
  File "/Users/kaseykwong/heart_rate_sentinel_server/.venv/lib/python3.6/site-packages/flask/app.py", line 1799, in dispatch_request
    return self.view_functions[rule.endpoint](**req.view_args)
  File "server.py", line 125, in heart_rate
    add_heart_rate(patient_number, hr, curr_time)
  File "server.py", line 143, in add_heart_rate
    if p.heart_rate_time[0] == p.created:
AttributeError: 'Patient' object has no attribute 'heart_rate_times'
11/15/2018 03:57:11 PM 127.0.0.1 - - [15/Nov/2018 15:57:11] "POST /api/heart_rate HTTP/1.1" 500 -
11/15/2018 03:57:26 PM Data input is OK. 
11/15/2018 03:57:27 PM 127.0.0.1 - - [15/Nov/2018 15:57:27] "POST /api/heart_rate HTTP/1.1" 200 -
11/15/2018 03:57:36 PM 127.0.0.1 - - [15/Nov/2018 15:57:36] "GET /api/heart_rate/2 HTTP/1.1" 200 -
11/15/2018 03:57:53 PM Data input is OK. 
11/15/2018 03:57:53 PM New Patient Added. 
11/15/2018 03:57:53 PM 127.0.0.1 - - [15/Nov/2018 15:57:53] "POST /api/new_patient HTTP/1.1" 200 -
11/15/2018 03:58:03 PM 127.0.0.1 - - [15/Nov/2018 15:58:03] "GET /api/heart_rate/2 HTTP/1.1" 200 -
11/15/2018 03:59:59 PM Data input is OK. 
11/15/2018 03:59:59 PM Patient_ID already exists, please enter new ID. 
11/15/2018 03:59:59 PM 127.0.0.1 - - [15/Nov/2018 15:59:59] "POST /api/new_patient HTTP/1.1" 400 -
11/15/2018 04:00:01 PM 127.0.0.1 - - [15/Nov/2018 16:00:01] "GET /api/heart_rate/2 HTTP/1.1" 200 -
11/15/2018 04:04:12 PM Data input is OK. 
11/15/2018 04:04:12 PM 127.0.0.1 - - [15/Nov/2018 16:04:12] "POST /api/heart_rate HTTP/1.1" 200 -
11/15/2018 04:04:17 PM 127.0.0.1 - - [15/Nov/2018 16:04:17] "GET /api/heart_rate/2 HTTP/1.1" 200 -
11/15/2018 04:04:39 PM Data input is OK. 
11/15/2018 04:04:39 PM Exception on /api/heart_rate [POST]
Traceback (most recent call last):
  File "/Users/kaseykwong/heart_rate_sentinel_server/.venv/lib/python3.6/site-packages/flask/app.py", line 2292, in wsgi_app
    response = self.full_dispatch_request()
  File "/Users/kaseykwong/heart_rate_sentinel_server/.venv/lib/python3.6/site-packages/flask/app.py", line 1815, in full_dispatch_request
    rv = self.handle_user_exception(e)
  File "/Users/kaseykwong/heart_rate_sentinel_server/.venv/lib/python3.6/site-packages/flask/app.py", line 1718, in handle_user_exception
    reraise(exc_type, exc_value, tb)
  File "/Users/kaseykwong/heart_rate_sentinel_server/.venv/lib/python3.6/site-packages/flask/_compat.py", line 35, in reraise
    raise value
  File "/Users/kaseykwong/heart_rate_sentinel_server/.venv/lib/python3.6/site-packages/flask/app.py", line 1813, in full_dispatch_request
    rv = self.dispatch_request()
  File "/Users/kaseykwong/heart_rate_sentinel_server/.venv/lib/python3.6/site-packages/flask/app.py", line 1799, in dispatch_request
    return self.view_functions[rule.endpoint](**req.view_args)
  File "server.py", line 125, in heart_rate
    add_heart_rate(patient_number, hr, curr_time)
  File "server.py", line 150, in add_heart_rate
    send_email(p.attending_email, patient_id)
  File "server.py", line 162, in send_email
    response = sg.client.mail.send.post(request_body=mail.get())
  File "/Users/kaseykwong/heart_rate_sentinel_server/.venv/lib/python3.6/site-packages/python_http_client/client.py", line 252, in http_request
    return Response(self._make_request(opener, request, timeout=timeout))
  File "/Users/kaseykwong/heart_rate_sentinel_server/.venv/lib/python3.6/site-packages/python_http_client/client.py", line 176, in _make_request
    raise exc
python_http_client.exceptions.UnauthorizedError: HTTP Error 401: Unauthorized
11/15/2018 04:04:39 PM 127.0.0.1 - - [15/Nov/2018 16:04:39] "POST /api/heart_rate HTTP/1.1" 500 -
11/15/2018 04:11:45 PM Data input is OK. 
11/15/2018 04:11:46 PM Exception on /api/heart_rate [POST]
Traceback (most recent call last):
  File "/Users/kaseykwong/heart_rate_sentinel_server/.venv/lib/python3.6/site-packages/flask/app.py", line 2292, in wsgi_app
    response = self.full_dispatch_request()
  File "/Users/kaseykwong/heart_rate_sentinel_server/.venv/lib/python3.6/site-packages/flask/app.py", line 1815, in full_dispatch_request
    rv = self.handle_user_exception(e)
  File "/Users/kaseykwong/heart_rate_sentinel_server/.venv/lib/python3.6/site-packages/flask/app.py", line 1718, in handle_user_exception
    reraise(exc_type, exc_value, tb)
  File "/Users/kaseykwong/heart_rate_sentinel_server/.venv/lib/python3.6/site-packages/flask/_compat.py", line 35, in reraise
    raise value
  File "/Users/kaseykwong/heart_rate_sentinel_server/.venv/lib/python3.6/site-packages/flask/app.py", line 1813, in full_dispatch_request
    rv = self.dispatch_request()
  File "/Users/kaseykwong/heart_rate_sentinel_server/.venv/lib/python3.6/site-packages/flask/app.py", line 1799, in dispatch_request
    return self.view_functions[rule.endpoint](**req.view_args)
  File "server.py", line 125, in heart_rate
    add_heart_rate(patient_number, hr, curr_time)
  File "server.py", line 150, in add_heart_rate
    send_email(p.attending_email, patient_id)
  File "server.py", line 162, in send_email
    response = sg.client.mail.send.post(request_body=mail.get())
  File "/Users/kaseykwong/heart_rate_sentinel_server/.venv/lib/python3.6/site-packages/python_http_client/client.py", line 252, in http_request
    return Response(self._make_request(opener, request, timeout=timeout))
  File "/Users/kaseykwong/heart_rate_sentinel_server/.venv/lib/python3.6/site-packages/python_http_client/client.py", line 176, in _make_request
    raise exc
python_http_client.exceptions.UnauthorizedError: HTTP Error 401: Unauthorized
11/15/2018 04:11:46 PM 127.0.0.1 - - [15/Nov/2018 16:11:46] "POST /api/heart_rate HTTP/1.1" 500 -
11/15/2018 04:15:50 PM Data input is OK. 
11/15/2018 04:15:50 PM Exception on /api/heart_rate [POST]
Traceback (most recent call last):
  File "/Users/kaseykwong/heart_rate_sentinel_server/.venv/lib/python3.6/site-packages/flask/app.py", line 2292, in wsgi_app
    response = self.full_dispatch_request()
  File "/Users/kaseykwong/heart_rate_sentinel_server/.venv/lib/python3.6/site-packages/flask/app.py", line 1815, in full_dispatch_request
    rv = self.handle_user_exception(e)
  File "/Users/kaseykwong/heart_rate_sentinel_server/.venv/lib/python3.6/site-packages/flask/app.py", line 1718, in handle_user_exception
    reraise(exc_type, exc_value, tb)
  File "/Users/kaseykwong/heart_rate_sentinel_server/.venv/lib/python3.6/site-packages/flask/_compat.py", line 35, in reraise
    raise value
  File "/Users/kaseykwong/heart_rate_sentinel_server/.venv/lib/python3.6/site-packages/flask/app.py", line 1813, in full_dispatch_request
    rv = self.dispatch_request()
  File "/Users/kaseykwong/heart_rate_sentinel_server/.venv/lib/python3.6/site-packages/flask/app.py", line 1799, in dispatch_request
    return self.view_functions[rule.endpoint](**req.view_args)
  File "server.py", line 125, in heart_rate
    add_heart_rate(patient_number, hr, curr_time)
  File "server.py", line 150, in add_heart_rate
    send_email(p.attending_email, patient_id)
  File "server.py", line 162, in send_email
    response = sg.client.mail.send.post(request_body=mail.get())
  File "/Users/kaseykwong/heart_rate_sentinel_server/.venv/lib/python3.6/site-packages/python_http_client/client.py", line 252, in http_request
    return Response(self._make_request(opener, request, timeout=timeout))
  File "/Users/kaseykwong/heart_rate_sentinel_server/.venv/lib/python3.6/site-packages/python_http_client/client.py", line 176, in _make_request
    raise exc
python_http_client.exceptions.UnauthorizedError: HTTP Error 401: Unauthorized
11/15/2018 04:15:50 PM 127.0.0.1 - - [15/Nov/2018 16:15:50] "POST /api/heart_rate HTTP/1.1" 500 -
11/15/2018 04:17:40 PM Data input is OK. 
11/15/2018 04:17:41 PM Exception on /api/heart_rate [POST]
Traceback (most recent call last):
  File "/Users/kaseykwong/heart_rate_sentinel_server/.venv/lib/python3.6/site-packages/flask/app.py", line 2292, in wsgi_app
    response = self.full_dispatch_request()
  File "/Users/kaseykwong/heart_rate_sentinel_server/.venv/lib/python3.6/site-packages/flask/app.py", line 1815, in full_dispatch_request
    rv = self.handle_user_exception(e)
  File "/Users/kaseykwong/heart_rate_sentinel_server/.venv/lib/python3.6/site-packages/flask/app.py", line 1718, in handle_user_exception
    reraise(exc_type, exc_value, tb)
  File "/Users/kaseykwong/heart_rate_sentinel_server/.venv/lib/python3.6/site-packages/flask/_compat.py", line 35, in reraise
    raise value
  File "/Users/kaseykwong/heart_rate_sentinel_server/.venv/lib/python3.6/site-packages/flask/app.py", line 1813, in full_dispatch_request
    rv = self.dispatch_request()
  File "/Users/kaseykwong/heart_rate_sentinel_server/.venv/lib/python3.6/site-packages/flask/app.py", line 1799, in dispatch_request
    return self.view_functions[rule.endpoint](**req.view_args)
  File "server.py", line 125, in heart_rate
    add_heart_rate(patient_number, hr, curr_time)
  File "server.py", line 150, in add_heart_rate
    send_email(p.attending_email, patient_id)
  File "server.py", line 162, in send_email
    response = sg.client.mail.send.post(request_body=mail.get())
  File "/Users/kaseykwong/heart_rate_sentinel_server/.venv/lib/python3.6/site-packages/python_http_client/client.py", line 252, in http_request
    return Response(self._make_request(opener, request, timeout=timeout))
  File "/Users/kaseykwong/heart_rate_sentinel_server/.venv/lib/python3.6/site-packages/python_http_client/client.py", line 176, in _make_request
    raise exc
python_http_client.exceptions.UnauthorizedError: HTTP Error 401: Unauthorized
11/15/2018 04:17:41 PM 127.0.0.1 - - [15/Nov/2018 16:17:41] "POST /api/heart_rate HTTP/1.1" 500 -
11/15/2018 04:25:50 PM Data input is OK. 
11/15/2018 04:25:50 PM Exception on /api/heart_rate [POST]
Traceback (most recent call last):
  File "/Users/kaseykwong/heart_rate_sentinel_server/.venv/lib/python3.6/site-packages/flask/app.py", line 2292, in wsgi_app
    response = self.full_dispatch_request()
  File "/Users/kaseykwong/heart_rate_sentinel_server/.venv/lib/python3.6/site-packages/flask/app.py", line 1815, in full_dispatch_request
    rv = self.handle_user_exception(e)
  File "/Users/kaseykwong/heart_rate_sentinel_server/.venv/lib/python3.6/site-packages/flask/app.py", line 1718, in handle_user_exception
    reraise(exc_type, exc_value, tb)
  File "/Users/kaseykwong/heart_rate_sentinel_server/.venv/lib/python3.6/site-packages/flask/_compat.py", line 35, in reraise
    raise value
  File "/Users/kaseykwong/heart_rate_sentinel_server/.venv/lib/python3.6/site-packages/flask/app.py", line 1813, in full_dispatch_request
    rv = self.dispatch_request()
  File "/Users/kaseykwong/heart_rate_sentinel_server/.venv/lib/python3.6/site-packages/flask/app.py", line 1799, in dispatch_request
    return self.view_functions[rule.endpoint](**req.view_args)
  File "server.py", line 125, in heart_rate
    add_heart_rate(patient_number, hr, curr_time)
  File "server.py", line 150, in add_heart_rate
    send_email(p.attending_email, patient_id)
  File "server.py", line 162, in send_email
    response = sg.client.mail.send.post(request_body=mail.get())
  File "/Users/kaseykwong/heart_rate_sentinel_server/.venv/lib/python3.6/site-packages/python_http_client/client.py", line 252, in http_request
    return Response(self._make_request(opener, request, timeout=timeout))
  File "/Users/kaseykwong/heart_rate_sentinel_server/.venv/lib/python3.6/site-packages/python_http_client/client.py", line 176, in _make_request
    raise exc
python_http_client.exceptions.UnauthorizedError: HTTP Error 401: Unauthorized
11/15/2018 04:25:50 PM 127.0.0.1 - - [15/Nov/2018 16:25:50] "POST /api/heart_rate HTTP/1.1" 500 -
11/15/2018 05:23:22 PM Data input is OK. 
11/15/2018 05:23:23 PM 127.0.0.1 - - [15/Nov/2018 17:23:23] "POST /api/heart_rate HTTP/1.1" 200 -
11/15/2018 05:24:08 PM 127.0.0.1 - - [15/Nov/2018 17:24:08] "GET /api/heart_rate/2 HTTP/1.1" 200 -
11/15/2018 05:36:02 PM 127.0.0.1 - - [15/Nov/2018 17:36:02] "GET /api/status/2 HTTP/1.1" 200 -
11/15/2018 05:45:55 PM 127.0.0.1 - - [15/Nov/2018 17:45:55] "GET /api/heart_rate/2 HTTP/1.1" 200 -
11/15/2018 05:46:51 PM Exception on /api/heart_rate/average/2 [GET]
Traceback (most recent call last):
  File "/Users/kaseykwong/heart_rate_sentinel_server/.venv/lib/python3.6/site-packages/flask/app.py", line 2292, in wsgi_app
    response = self.full_dispatch_request()
  File "/Users/kaseykwong/heart_rate_sentinel_server/.venv/lib/python3.6/site-packages/flask/app.py", line 1815, in full_dispatch_request
    rv = self.handle_user_exception(e)
  File "/Users/kaseykwong/heart_rate_sentinel_server/.venv/lib/python3.6/site-packages/flask/app.py", line 1718, in handle_user_exception
    reraise(exc_type, exc_value, tb)
  File "/Users/kaseykwong/heart_rate_sentinel_server/.venv/lib/python3.6/site-packages/flask/_compat.py", line 35, in reraise
    raise value
  File "/Users/kaseykwong/heart_rate_sentinel_server/.venv/lib/python3.6/site-packages/flask/app.py", line 1813, in full_dispatch_request
    rv = self.dispatch_request()
  File "/Users/kaseykwong/heart_rate_sentinel_server/.venv/lib/python3.6/site-packages/flask/app.py", line 1799, in dispatch_request
    return self.view_functions[rule.endpoint](**req.view_args)
  File "server.py", line 279, in average_patient
    av = average_hr(hr)
  File "server.py", line 295, in average_hr
    average = np.mean(hr)
  File "/Users/kaseykwong/heart_rate_sentinel_server/.venv/lib/python3.6/site-packages/numpy/core/fromnumeric.py", line 2920, in mean
    out=out, **kwargs)
  File "/Users/kaseykwong/heart_rate_sentinel_server/.venv/lib/python3.6/site-packages/numpy/core/_methods.py", line 75, in _mean
    ret = umr_sum(arr, axis, dtype, out, keepdims)
TypeError: unsupported operand type(s) for +: 'int' and 'datetime.datetime'
11/15/2018 05:46:51 PM 127.0.0.1 - - [15/Nov/2018 17:46:51] "GET /api/heart_rate/average/2 HTTP/1.1" 500 -
11/15/2018 05:49:01 PM Average heart rate calculated successfully.
11/15/2018 05:49:01 PM 127.0.0.1 - - [15/Nov/2018 17:49:01] "GET /api/heart_rate/average/2 HTTP/1.1" 200 -
11/15/2018 05:51:15 PM Time requested is valid: 2018-07-09 11:00:36.378429
11/15/2018 05:51:15 PM Data input is OK. 
11/15/2018 05:51:15 PM No data associated with patient id.
11/15/2018 05:51:15 PM 127.0.0.1 - - [15/Nov/2018 17:51:15] "POST /api/heart_rate/interval_average HTTP/1.1" 400 -
11/15/2018 05:51:30 PM Time requested is valid: 2018-07-09 11:00:36.378429
11/15/2018 05:51:30 PM Data input is OK. 
11/15/2018 05:51:30 PM Exception on /api/heart_rate/interval_average [POST]
Traceback (most recent call last):
  File "/Users/kaseykwong/heart_rate_sentinel_server/.venv/lib/python3.6/site-packages/flask/app.py", line 2292, in wsgi_app
    response = self.full_dispatch_request()
  File "/Users/kaseykwong/heart_rate_sentinel_server/.venv/lib/python3.6/site-packages/flask/app.py", line 1815, in full_dispatch_request
    rv = self.handle_user_exception(e)
  File "/Users/kaseykwong/heart_rate_sentinel_server/.venv/lib/python3.6/site-packages/flask/app.py", line 1718, in handle_user_exception
    reraise(exc_type, exc_value, tb)
  File "/Users/kaseykwong/heart_rate_sentinel_server/.venv/lib/python3.6/site-packages/flask/_compat.py", line 35, in reraise
    raise value
  File "/Users/kaseykwong/heart_rate_sentinel_server/.venv/lib/python3.6/site-packages/flask/app.py", line 1813, in full_dispatch_request
    rv = self.dispatch_request()
  File "/Users/kaseykwong/heart_rate_sentinel_server/.venv/lib/python3.6/site-packages/flask/app.py", line 1799, in dispatch_request
    return self.view_functions[rule.endpoint](**req.view_args)
  File "server.py", line 317, in interval_average
    int_avg = interval(hr, hr_t, t_since)
  File "server.py", line 341, in interval
    if t > t_since:
TypeError: '>' not supported between instances of 'datetime.datetime' and 'str'
11/15/2018 05:51:30 PM 127.0.0.1 - - [15/Nov/2018 17:51:30] "POST /api/heart_rate/interval_average HTTP/1.1" 500 -
11/15/2018 05:52:50 PM Time requested is valid: 2018-07-09 11:00:36.378429
11/15/2018 05:52:50 PM Data input is OK. 
11/15/2018 05:52:51 PM Exception on /api/heart_rate/interval_average [POST]
Traceback (most recent call last):
  File "/Users/kaseykwong/heart_rate_sentinel_server/.venv/lib/python3.6/site-packages/flask/app.py", line 2292, in wsgi_app
    response = self.full_dispatch_request()
  File "/Users/kaseykwong/heart_rate_sentinel_server/.venv/lib/python3.6/site-packages/flask/app.py", line 1815, in full_dispatch_request
    rv = self.handle_user_exception(e)
  File "/Users/kaseykwong/heart_rate_sentinel_server/.venv/lib/python3.6/site-packages/flask/app.py", line 1718, in handle_user_exception
    reraise(exc_type, exc_value, tb)
  File "/Users/kaseykwong/heart_rate_sentinel_server/.venv/lib/python3.6/site-packages/flask/_compat.py", line 35, in reraise
    raise value
  File "/Users/kaseykwong/heart_rate_sentinel_server/.venv/lib/python3.6/site-packages/flask/app.py", line 1813, in full_dispatch_request
    rv = self.dispatch_request()
  File "/Users/kaseykwong/heart_rate_sentinel_server/.venv/lib/python3.6/site-packages/flask/app.py", line 1799, in dispatch_request
    return self.view_functions[rule.endpoint](**req.view_args)
  File "server.py", line 317, in interval_average
    int_avg = interval(hr, hr_t, t_since)
  File "server.py", line 341, in interval
    if t > datetime.strptime(t_since):
TypeError: strptime() takes exactly 2 arguments (1 given)
11/15/2018 05:52:51 PM 127.0.0.1 - - [15/Nov/2018 17:52:51] "POST /api/heart_rate/interval_average HTTP/1.1" 500 -
11/15/2018 05:53:31 PM Time requested is valid: 2018-07-09 11:00:36.378429
11/15/2018 05:53:31 PM Data input is OK. 
11/15/2018 05:53:31 PM Average heart rate calculated successfully.
11/15/2018 05:53:31 PM 127.0.0.1 - - [15/Nov/2018 17:53:31] "POST /api/heart_rate/interval_average HTTP/1.1" 200 -
11/15/2018 05:54:47 PM Time requested is valid: 2018-07-09 11:00:36.378429
11/15/2018 05:54:47 PM Data input is OK. 
11/15/2018 05:54:47 PM No data associated with patient id.
11/15/2018 05:54:47 PM 127.0.0.1 - - [15/Nov/2018 17:54:47] "POST /api/heart_rate/interval_average HTTP/1.1" 400 -
11/15/2018 05:57:29 PM Time requested is valid: 2018-07-09 11:00:36.378429
11/15/2018 05:57:29 PM Data input is OK. 
11/15/2018 05:57:29 PM Average heart rate calculated successfully.
11/15/2018 05:57:29 PM 127.0.0.1 - - [15/Nov/2018 17:57:29] "POST /api/heart_rate/interval_average HTTP/1.1" 200 -
11/15/2018 08:33:03 PM Time requested is valid: 2018-07-09 11:00:36.378429
11/15/2018 08:33:03 PM Data input is OK. 
11/15/2018 08:33:03 PM Exception on /api/heart_rate/interval_average [POST]
Traceback (most recent call last):
  File "/Users/kaseykwong/heart_rate_sentinel_server/.venv/lib/python3.6/site-packages/flask/app.py", line 2292, in wsgi_app
    response = self.full_dispatch_request()
  File "/Users/kaseykwong/heart_rate_sentinel_server/.venv/lib/python3.6/site-packages/flask/app.py", line 1815, in full_dispatch_request
    rv = self.handle_user_exception(e)
  File "/Users/kaseykwong/heart_rate_sentinel_server/.venv/lib/python3.6/site-packages/flask/app.py", line 1718, in handle_user_exception
    reraise(exc_type, exc_value, tb)
  File "/Users/kaseykwong/heart_rate_sentinel_server/.venv/lib/python3.6/site-packages/flask/_compat.py", line 35, in reraise
    raise value
  File "/Users/kaseykwong/heart_rate_sentinel_server/.venv/lib/python3.6/site-packages/flask/app.py", line 1813, in full_dispatch_request
    rv = self.dispatch_request()
  File "/Users/kaseykwong/heart_rate_sentinel_server/.venv/lib/python3.6/site-packages/flask/app.py", line 1799, in dispatch_request
    return self.view_functions[rule.endpoint](**req.view_args)
  File "server.py", line 317, in interval_average
    int_avg = interval(hr, hr_t, t_since)
  File "server.py", line 341, in interval
    if datetime.strptime(t,"%Y-%m-%d %H:%M:%S.%f") > datetime.strptime(t_since,"%Y-%m-%d %H:%M:%S.%f"):
TypeError: strptime() argument 1 must be str, not datetime.datetime
11/15/2018 08:33:03 PM 127.0.0.1 - - [15/Nov/2018 20:33:03] "POST /api/heart_rate/interval_average HTTP/1.1" 500 -
11/15/2018 08:36:17 PM Time requested is valid: 2018-07-09 11:00:36.378429
11/15/2018 08:36:17 PM Data input is OK. 
11/15/2018 08:36:17 PM Average heart rate calculated successfully.
11/15/2018 08:36:17 PM 127.0.0.1 - - [15/Nov/2018 20:36:17] "POST /api/heart_rate/interval_average HTTP/1.1" 200 -
11/16/2018 12:46:50 PM Average heart rate calculated successfully.
11/16/2018 12:46:50 PM 127.0.0.1 - - [16/Nov/2018 12:46:50] "GET /api/heart_rate/average/2 HTTP/1.1" 200 -
12/05/2018 05:52:14 PM Data input is OK. 
12/05/2018 05:52:14 PM Patient_ID already exists, please enter new ID. 
12/05/2018 05:52:14 PM 127.0.0.1 - - [05/Dec/2018 17:52:14] "POST /api/new_patient HTTP/1.1" 400 -
12/05/2018 05:53:32 PM Data input is OK. 
12/05/2018 05:53:32 PM Patient_ID already exists, please enter new ID. 
12/05/2018 05:53:32 PM 127.0.0.1 - - [05/Dec/2018 17:53:32] "POST /api/new_patient HTTP/1.1" 400 -
12/05/2018 05:54:35 PM Data input is OK. 
12/05/2018 05:54:35 PM Patient_ID already exists, please enter new ID. 
12/05/2018 05:54:35 PM 127.0.0.1 - - [05/Dec/2018 17:54:35] "POST /api/new_patient HTTP/1.1" 400 -
12/05/2018 05:54:44 PM Data input is OK. 
12/05/2018 05:54:44 PM Patient_ID already exists, please enter new ID. 
12/05/2018 05:54:44 PM 127.0.0.1 - - [05/Dec/2018 17:54:44] "POST /api/new_patient HTTP/1.1" 400 -
12/05/2018 06:00:00 PM Data input is OK. 
12/05/2018 06:00:00 PM New Patient Added. 
12/05/2018 06:00:00 PM 127.0.0.1 - - [05/Dec/2018 18:00:00] "POST /api/new_patient HTTP/1.1" 200 -
12/05/2018 06:00:46 PM Data input is OK. 
12/05/2018 06:00:46 PM New Patient Added. 
12/05/2018 06:00:46 PM 127.0.0.1 - - [05/Dec/2018 18:00:46] "POST /api/new_patient HTTP/1.1" 200 -
12/05/2018 06:01:17 PM Data input is OK. 
12/05/2018 06:01:17 PM Patient_ID already exists, please enter new ID. 
12/05/2018 06:01:17 PM 127.0.0.1 - - [05/Dec/2018 18:01:17] "POST /api/new_patient HTTP/1.1" 400 -
